<?xml version="1.0" encoding="utf-8"?>
<!-- This URDF was automatically created by SolidWorks to URDF Exporter! Originally created by Stephen Brawner (brawner@gmail.com) 
     Commit Version: 1.6.0-1-g15f4949  Build Version: 1.6.7594.29634
     For more information, please see http://wiki.ros.org/sw_urdf_exporter -->
<robot
  name="zebrat">
  <link
    name="base_link">
    <inertial>
      <origin
        xyz="0.070574 -0.0043486 -0.067094"
        rpy="0 0 0" />
      <mass
        value="35.776" />
      <inertia
        ixx="0.43687"
        ixy="-1.1422E-05"
        ixz="0.00084257"
        iyy="0.44998"
        iyz="4.6829E-06"
        izz="0.69497" />
    </inertial>
    <visual>
      <origin
        xyz="0 0 0"
        rpy="0 0 0" />
      <geometry>
        <mesh
          filename="package://zebrat/meshes/base_link.STL" />
      </geometry>
      <material
        name="">
        <color
          rgba="1 1 1 1" />
      </material>
    </visual>
    <collision>
      <origin
        xyz="0 0 0"
        rpy="0 0 0" />
      <geometry>
        <mesh
          filename="package://zebrat/meshes/base_link.STL" />
      </geometry>
    </collision>
  </link>
  <link
    name="lr_wheel">
    <inertial>
      <origin
        xyz="3.0351E-07 7.0113E-05 5.1237E-07"
        rpy="0 0 0" />
      <mass
        value="1.1552" />
      <inertia
        ixx="0.011871"
        ixy="2.7831E-11"
        ixz="1.6436E-09"
        iyy="0.020263"
        iyz="-8.4684E-12"
        izz="0.011871" />
    </inertial>
    <visual>
      <origin
        xyz="0 0 0"
        rpy="0 0 0" />
      <geometry>
        <mesh
          filename="package://zebrat/meshes/lr_wheel.STL" />
      </geometry>
      <material
        name="">
        <color
          rgba="0.69804 0.69804 0.69804 1" />
      </material>
    </visual>
    <collision>
      <origin
        xyz="0 0 0"
        rpy="0 0 0" />
      <geometry>
        <mesh
          filename="package://zebrat/meshes/lr_wheel.STL" />
      </geometry>
    </collision>
  </link>
  <joint
    name="base2lr"
    type="continuous">
    <origin
      xyz="-0.2709 0.27237 -0.22667"
      rpy="0 0 0" />
    <parent
      link="base_link" />
    <child
      link="lr_wheel" />
    <axis
      xyz="0 -1 0" />
  </joint>
  <link
    name="rr_wheel">
    <inertial>
      <origin
        xyz="-3.0351E-07 -7.0113E-05 5.1237E-07"
        rpy="0 0 0" />
      <mass
        value="1.1552" />
      <inertia
        ixx="0.011871"
        ixy="2.7831E-11"
        ixz="-1.6436E-09"
        iyy="0.020263"
        iyz="8.4684E-12"
        izz="0.011871" />
    </inertial>
    <visual>
      <origin
        xyz="0 0 0"
        rpy="0 0 0" />
      <geometry>
        <mesh
          filename="package://zebrat/meshes/rr_wheel.STL" />
      </geometry>
      <material
        name="">
        <color
          rgba="0.69804 0.69804 0.69804 1" />
      </material>
    </visual>
    <collision>
      <origin
        xyz="0 0 0"
        rpy="0 0 0" />
      <geometry>
        <mesh
          filename="package://zebrat/meshes/rr_wheel.STL" />
      </geometry>
    </collision>
  </link>
  <joint
    name="base2rr"
    type="continuous">
    <origin
      xyz="-0.2709 -0.27237 -0.22667"
      rpy="0 0 0" />
    <parent
      link="base_link" />
    <child
      link="rr_wheel" />
    <axis
      xyz="0 -1 0" />
  </joint>
  <link
    name="lstr_link">
    <inertial>
      <origin
        xyz="5.5511E-17 0 -0.025"
        rpy="0 0 0" />
      <mass
        value="0.14579" />
      <inertia
        ixx="9.1697E-05"
        ixy="3.1179E-23"
        ixz="7.588E-20"
        iyy="9.1697E-05"
        iyz="-1.876E-20"
        izz="6.5014E-06" />
    </inertial>
    <visual>
      <origin
        xyz="0 0 0"
        rpy="0 0 0" />
      <geometry>
        <mesh
          filename="package://zebrat/meshes/lstr_link.STL" />
      </geometry>
      <material
        name="">
        <color
          rgba="0.69804 0.69804 0.69804 1" />
      </material>
    </visual>
    <collision>
      <origin
        xyz="0 0 0"
        rpy="0 0 0" />
      <geometry>
        <mesh
          filename="package://zebrat/meshes/lstr_link.STL" />
      </geometry>
    </collision>
  </link>
  <joint
    name="bast2lstr"
    type="revolute">
    <origin
      xyz="0.2891 0.21125 -0.20084"
      rpy="0 0 0" />
    <parent
      link="base_link" />
    <child
      link="lstr_link" />
    <axis
      xyz="0 0 -1" />
    <limit
      lower="0"
      upper="0"
      effort="0"
      velocity="0" />
  </joint>
  <link
    name="lf_wheel">
    <inertial>
      <origin
        xyz="-3.3596E-07 -0.0053454 -1.922E-07"
        rpy="0 0 0" />
      <mass
        value="1.7625" />
      <inertia
        ixx="0.012197"
        ixy="-4.1791E-12"
        ixz="1.5688E-09"
        iyy="0.020893"
        iyz="2.7769E-11"
        izz="0.012197" />
    </inertial>
    <visual>
      <origin
        xyz="0 0 0"
        rpy="0 0 0" />
      <geometry>
        <mesh
          filename="package://zebrat/meshes/lf_wheel.STL" />
      </geometry>
      <material
        name="">
        <color
          rgba="0.69804 0.69804 0.69804 1" />
      </material>
    </visual>
    <collision>
      <origin
        xyz="0 0 0"
        rpy="0 0 0" />
      <geometry>
        <mesh
          filename="package://zebrat/meshes/lf_wheel.STL" />
      </geometry>
    </collision>
  </link>
  <joint
    name="lstr2lf"
    type="continuous">
    <origin
      xyz="0 0.0655 -0.031746"
      rpy="0 0 0" />
    <parent
      link="lstr_link" />
    <child
      link="lf_wheel" />
    <axis
      xyz="0 1 0" />
  </joint>
  <link
    name="rstr_link">
    <inertial>
      <origin
        xyz="-1.1102E-16 -2.7756E-17 -0.025"
        rpy="0 0 0" />
      <mass
        value="0.14579" />
      <inertia
        ixx="9.1697E-05"
        ixy="3.1694E-23"
        ixz="-1.0543E-19"
        iyy="9.1697E-05"
        iyz="1.8742E-20"
        izz="6.5014E-06" />
    </inertial>
    <visual>
      <origin
        xyz="0 0 0"
        rpy="0 0 0" />
      <geometry>
        <mesh
          filename="package://zebrat/meshes/rstr_link.STL" />
      </geometry>
      <material
        name="">
        <color
          rgba="0.69804 0.69804 0.69804 1" />
      </material>
    </visual>
    <collision>
      <origin
        xyz="0 0 0"
        rpy="0 0 0" />
      <geometry>
        <mesh
          filename="package://zebrat/meshes/rstr_link.STL" />
      </geometry>
    </collision>
  </link>
  <joint
    name="base2rstr"
    type="revolute">
    <origin
      xyz="0.2891 -0.21125 -0.20084"
      rpy="0 0 0" />
    <parent
      link="base_link" />
    <child
      link="rstr_link" />
    <axis
      xyz="0 0 -1" />
    <limit
      lower="0"
      upper="0"
      effort="0"
      velocity="0" />
  </joint>
  <link
    name="rf_wheel">
    <inertial>
      <origin
        xyz="-3.3596E-07 0.0053454 1.922E-07"
        rpy="0 0 0" />
      <mass
        value="1.7625" />
      <inertia
        ixx="0.012197"
        ixy="3.9087E-12"
        ixz="-1.5688E-09"
        iyy="0.020893"
        iyz="2.7769E-11"
        izz="0.012197" />
    </inertial>
    <visual>
      <origin
        xyz="0 0 0"
        rpy="0 0 0" />
      <geometry>
        <mesh
          filename="package://zebrat/meshes/rf_wheel.STL" />
      </geometry>
      <material
        name="">
        <color
          rgba="0.69804 0.69804 0.69804 1" />
      </material>
    </visual>
    <collision>
      <origin
        xyz="0 0 0"
        rpy="0 0 0" />
      <geometry>
        <mesh
          filename="package://zebrat/meshes/rf_wheel.STL" />
      </geometry>
    </collision>
  </link>
  <joint
    name="rstr2rf"
    type="continuous">
    <origin
      xyz="0 -0.0655 -0.031746"
      rpy="0 0 0" />
    <parent
      link="rstr_link" />
    <child
      link="rf_wheel" />
    <axis
      xyz="0 -1 0" />
  </joint>
</robot>