<?xml version="1.0" encoding="utf-8"?>
<!-- This URDF was automatically created by SolidWorks to URDF Exporter! Originally created by Stephen Brawner (brawner@gmail.com) 
     Commit Version: 1.6.0-1-g15f4949  Build Version: 1.6.7594.29634
     For more information, please see http://wiki.ros.org/sw_urdf_exporter -->
<!--<robot
  name="zebrat">-->
<robot name="zebrat" xmlns:xacro="http://www.ros.org/wiki/xacro">

  <xacro:arg name="gpu" default="false"/>
  <xacro:property name="gpu" value="$(arg gpu)" />
  <xacro:arg name="organize_cloud" default="false"/>
  <xacro:property name="organize_cloud" value="$(arg organize_cloud)" />

  <xacro:include filename="$(find velodyne_description)/urdf/VLP-16.urdf.xacro"/>
  <xacro:VLP-16 parent="base_link" name="velodyne" topic="/velodyne_points" organize_cloud="${organize_cloud}" hz="10" samples="440" gpu="${gpu}">
    <origin xyz="0.38 0 0.07" rpy="0 0 0" />
  </xacro:VLP-16>

  <xacro:include filename="$(find zebrat)/urdf/sensors/lidar.xacro" />
  <joint name="lidar_joint" type="fixed">
    <origin xyz="0.4 0 0.5" rpy="0 0 0" />
    <parent link="base_link"/>
    <child link="laser_link"/>
  </joint>
  <lidar prefix="laser"/>

  <!--<xacro:include filename="$(find zebrat)/urdf/sensors/camera.xacro" />
  <joint name="camera_joint" type="fixed">
    <origin xyz="0.5 0.0 0.0" rpy="0 0 0" />
    <parent link="base_link"/>
    <child link="camera_link"/>
  </joint>-->

  <xacro:include filename="$(find zebrat)/urdf/sensors/imu.xacro" />
  <joint name="imu_joint" type="fixed">
    <origin  xyz="0.0 0 0" rpy="0 0 0" />
    <parent link="base_link"/>
    <child link="imu_link"/>
  </joint>
  <imu prefix="imu"/>

  <material name="Blue">
    <color rgba="0 0 1 1"/>
  </material>
  <material name="Grey">
    <color rgba="0.5 0.5 0.5 1"/>
  </material>
  <material name="Black">
    <color rgba="0 0 0 1"/>
  </material>
  <material name="Green">
    <color rgba="0.25 0.8 0.25 1"/>
  </material>


  <link name="base_footprint"/>
  

  <link
    name="base_link">
    <inertial>
      <origin
        xyz="0.070574 -0.0043486 -0.067094"
        rpy="0 0 0" />
      <mass
        value="35.776" />
      <inertia
        ixx="2.14656"
        ixy="0.0"
        ixz="0.0"
        iyy="4.0546"
        iyz="0.0"
        izz="4.0546" />
    </inertial>
    <visual>
      <origin
        xyz="0 0 0"
        rpy="0 0 0" />
      <geometry>
        <mesh
          filename="package://zebrat/meshes/base_link.STL" />
      </geometry>
      <material
        name="Green">
        <color rgba="0.13 0.54 0.13 1.0"/>
      </material>
    </visual>
    <!--<visual>
      <origin
        xyz="0 0 0"
        rpy="0 0 0" />
      <geometry>
        <box size = "1.0 0.6 0.6"/>
      </geometry>
      <material
        name="Green">
        <color rgba="0.13 0.54 0.13 1.0"/>
      </material>
    </visual>-->
    <collision>
      <origin
        xyz="0 0 0"
        rpy="0 0 0" />
      <geometry>
        <box size = "1.0 0.6 0.6"/>
      </geometry>
    </collision>
  </link>
  <gazebo reference="$base_link">
    <material>Gazebo/Green</material>
  </gazebo>

  <joint
    name="footprint2base"
    type="fixed">
    <origin
      xyz="0 0 0.45"
      rpy="0 0 0" />
    <parent
      link="base_footprint" />
    <child
      link="base_link" />
    <axis
      xyz="0 0 0" />
  </joint>



  <link
    name="rl_wheel">
    <inertial>
      <origin
        xyz="3.0351E-07 7.0113E-05 5.1237E-07"
        rpy="0 0 0" />
      <mass
        value="1.1552" />
      <inertia
        ixx="0.011871"
        ixy="2.7831E-11"
        ixz="1.6436E-09"
        iyy="0.020263"
        iyz="-8.4684E-12"
        izz="0.011871" />
    </inertial>
    <visual>
      <origin
        xyz="0 0 0"
        rpy="0 0 0" />
      <geometry>
        <mesh
          filename="package://zebrat/meshes/lr_wheel.STL" />
      </geometry>
      <material
        name="">
        <color
          rgba="0.69804 0.69804 0.69804 1" />
      </material>
    </visual>
    <collision>
      <origin
        xyz="0 0 0"
        rpy="0 0 0" />
      <geometry>
        <mesh
          filename="package://zebrat/meshes/lr_wheel.STL" />
      </geometry>
    </collision>
  </link>
  <gazebo reference="$rl_wheel">
    <material>Gazebo/Black</material>
  </gazebo>

  <gazebo>
    <plugin name="gazebo_ros_control" filename="libgazebo_ros_control.so">
    <legacyModeNS>true</legacyModeNS>
    <robotSimType>gazebo_ros_control/DefaultRobotHWSim</robotSimType>
    <robotNamespace>/zebrat</robotNamespace>
    </plugin>
  </gazebo>



  <joint
    name="rl_axle"
    type="continuous">
    <origin
      xyz="-0.2709 0.27237 -0.22667"
      rpy="0 0 0" />
    <parent
      link="base_link" />
    <child
      link="rl_wheel" />
    <axis
      xyz="0 1 0" />
    <limit
      effort="100.0"
      velocity="200.0" />
  </joint>
  <transmission name="rl_tran">
    <type>transmission_interface/SimpleTransmission</type>
    <joint name="rl_axle">
      <hardwareInterface>hardware_interface/EffortJointInterface</hardwareInterface>
    </joint>
    <actuator name="rl_act">
      <!-- This hardwareInterface element exists for compatibility
           with ROS Hydro. -->
      <hardwareInterface>hardware_interface/EffortJointInterface</hardwareInterface>
      <mechanicalReduction>1</mechanicalReduction>
    </actuator>
  </transmission>


  <link
    name="rr_wheel">
    <inertial>
      <origin
        xyz="-3.0351E-07 -7.0113E-05 5.1237E-07"
        rpy="0 0 0" />
      <mass
        value="1.1552" />
      <inertia
        ixx="0.011871"
        ixy="2.7831E-11"
        ixz="-1.6436E-09"
        iyy="0.020263"
        iyz="8.4684E-12"
        izz="0.011871" />
    </inertial>
    <visual>
      <origin
        xyz="0 0 0"
        rpy="0 0 0" />
      <geometry>
        <mesh
          filename="package://zebrat/meshes/rr_wheel.STL" />
      </geometry>
      <material
        name="">
        <color
          rgba="0.69804 0.69804 0.69804 1" />
      </material>
    </visual>
    <collision>
      <origin
        xyz="0 0 0"
        rpy="0 0 0" />
      <geometry>
        <mesh
          filename="package://zebrat/meshes/rr_wheel.STL" />
      </geometry>
    </collision>
  </link>
  <gazebo reference="$rr_wheel">
    <material>Gazebo/Black</material>
  </gazebo>


  <joint
    name="rr_axle"
    type="continuous">
    <origin
      xyz="-0.2709 -0.27237 -0.22667"
      rpy="0 0 0" />
    <parent
      link="base_link" />
    <child
      link="rr_wheel" />
    <axis
      xyz="0 1 0" />
    <limit
      effort="100.0"
      velocity="200.0" />
  </joint>
  <transmission name="rr_tran">
    <type>transmission_interface/SimpleTransmission</type>
    <joint name="rr_axle">
      <hardwareInterface>hardware_interface/EffortJointInterface</hardwareInterface>
    </joint>
    <actuator name="rr_act">
      <!-- This hardwareInterface element exists for compatibility
           with ROS Hydro. -->
      <hardwareInterface>hardware_interface/EffortJointInterface</hardwareInterface>
      <mechanicalReduction>1</mechanicalReduction>
    </actuator>
  </transmission>




  <link
    name="lstr_link">
    <inertial>
      <origin
        xyz="5.5511E-17 0 -0.025"
        rpy="0 0 0" />
      <mass
        value="0.14579" />
      <inertia
        ixx="9.1697E-05"
        ixy="3.1179E-23"
        ixz="7.588E-20"
        iyy="9.1697E-05"
        iyz="-1.876E-20"
        izz="6.5014E-06" />
    </inertial>
    <visual>
      <origin
        xyz="0 0 0"
        rpy="0 0 0" />
      <geometry>
        <mesh
          filename="package://zebrat/meshes/lstr_link.STL" />
      </geometry>
      <material
        name="">
        <color
          rgba="0.69804 0.69804 0.69804 1" />
      </material>
    </visual>
    <collision>
      <origin
        xyz="0 0 0"
        rpy="0 0 0" />
      <geometry>
        <mesh
          filename="package://zebrat/meshes/lstr_link.STL" />
      </geometry>
    </collision>
  </link>
  <joint
    name="base2lstr"
    type="revolute">
    <origin
      xyz="0.2891 0.21125 -0.20084"
      rpy="0 0 0" />
    <parent
      link="base_link" />
    <child
      link="lstr_link" />
    <axis
      xyz="0 0 1" />
    <limit
      lower="-0.6"
      upper="0.6"
      effort="10.0"
      velocity="20.0" />
  </joint>

  <transmission name="lstr_tran">
    <type>transmission_interface/SimpleTransmission</type>
    <joint name="base2lstr">
      <hardwareInterface>hardware_interface/EffortJointInterface</hardwareInterface>
    </joint>
    <actuator name="lstr_act">
      <!-- This hardwareInterface element exists for compatibility
           with ROS Hydro. -->
      <hardwareInterface>hardware_interface/EffortJointInterface</hardwareInterface>
      <mechanicalReduction>1</mechanicalReduction>
    </actuator>
  </transmission>




  <link
    name="fl_wheel">
    <inertial>
      <origin
        xyz="-3.3596E-07 -0.0053454 -1.922E-07"
        rpy="0 0 0" />
      <mass
        value="1.7625" />
      <inertia
        ixx="0.012197"
        ixy="-4.1791E-12"
        ixz="1.5688E-09"
        iyy="0.020893"
        iyz="2.7769E-11"
        izz="0.012197" />
    </inertial>
    <visual>
      <origin
        xyz="0 0 0"
        rpy="0 0 0" />
      <geometry>
        <mesh
          filename="package://zebrat/meshes/lf_wheel.STL" />
      </geometry>
      <material
        name="">
        <color
          rgba="0.69804 0.69804 0.69804 1" />
      </material>
    </visual>
    <collision>
      <origin
        xyz="0 0 0"
        rpy="0 0 0" />
      <geometry>
        <mesh
          filename="package://zebrat/meshes/lf_wheel.STL" />
      </geometry>
    </collision>
  </link>
  <gazebo reference="$fl_wheel">
    <material>Gazebo/Black</material>
  </gazebo>


  <joint
    name="fl_axle"
    type="continuous">
    <origin
      xyz="0 0.0655 -0.031746"
      rpy="0 0 0" />
    <parent
      link="lstr_link" />
    <child
      link="fl_wheel" />
    <axis
      xyz="0 1 0" />
    <limit
      effort="100.0"
      velocity="200.0" />
  </joint>
  <transmission name="fl_tran">
    <type>transmission_interface/SimpleTransmission</type>
    <joint name="fl_axle">
      <hardwareInterface>hardware_interface/EffortJointInterface</hardwareInterface>
    </joint>
    <actuator name="fl_act">
      <!-- This hardwareInterface element exists for compatibility
           with ROS Hydro. -->
      <hardwareInterface>hardware_interface/EffortJointInterface</hardwareInterface>
      <mechanicalReduction>1</mechanicalReduction>
    </actuator>
  </transmission>


  <link
    name="rstr_link">
    <inertial>
      <origin
        xyz="-1.1102E-16 -2.7756E-17 -0.025"
        rpy="0 0 0" />
      <mass
        value="0.14579" />
      <inertia
        ixx="9.1697E-05"
        ixy="3.1694E-23"
        ixz="-1.0543E-19"
        iyy="9.1697E-05"
        iyz="1.8742E-20"
        izz="6.5014E-06" />
    </inertial>
    <visual>
      <origin
        xyz="0 0 0"
        rpy="0 0 0" />
      <geometry>
        <mesh
          filename="package://zebrat/meshes/rstr_link.STL" />
      </geometry>
      <material
        name="">
        <color
          rgba="0.69804 0.69804 0.69804 1" />
      </material>
    </visual>
    <collision>
      <origin
        xyz="0 0 0"
        rpy="0 0 0" />
      <geometry>
        <mesh
          filename="package://zebrat/meshes/rstr_link.STL" />
      </geometry>
    </collision>
  </link>

  <joint
    name="base2rstr"
    type="revolute">
    <origin
      xyz="0.2891 -0.21125 -0.20084"
      rpy="0 0 0" />
    <parent
      link="base_link" />
    <child
      link="rstr_link" />
    <axis
      xyz="0 0 1" />
    <limit
      lower="-0.6"
      upper="0.6"
      effort="10.0"
      velocity="20.0" />
  </joint>
  <transmission name="rstr_tran">
    <type>transmission_interface/SimpleTransmission</type>
    <joint name="base2rstr">
      <hardwareInterface>hardware_interface/EffortJointInterface</hardwareInterface>
    </joint>
    <actuator name="rstr_act">
      <!-- This hardwareInterface element exists for compatibility
           with ROS Hydro. -->
      <hardwareInterface>hardware_interface/EffortJointInterface</hardwareInterface>
      <mechanicalReduction>1</mechanicalReduction>
    </actuator>
  </transmission>





  <link
    name="fr_wheel">
    <inertial>
      <origin
        xyz="-3.3596E-07 0.0053454 1.922E-07"
        rpy="0 0 0" />
      <mass
        value="1.7625" />
      <inertia
        ixx="0.012197"
        ixy="3.9087E-12"
        ixz="-1.5688E-09"
        iyy="0.020893"
        iyz="2.7769E-11"
        izz="0.012197" />
    </inertial>
    <visual>
      <origin
        xyz="0 0 0"
        rpy="0 0 0" />
      <geometry>
        <mesh
          filename="package://zebrat/meshes/rf_wheel.STL" />
      </geometry>
      <material
        name="">
        <color
          rgba="0.69804 0.69804 0.69804 1" />
      </material>
    </visual>
    <collision>
      <origin
        xyz="0 0 0"
        rpy="0 0 0" />
      <geometry>
        <mesh
          filename="package://zebrat/meshes/rf_wheel.STL" />
      </geometry>
    </collision>
  </link>
  <gazebo reference="$fr_wheel">
    <material>Gazebo/Black</material>
  </gazebo>

  <joint
    name="fr_axle"
    type="continuous">
    <origin
      xyz="0 -0.0655 -0.031746"
      rpy="0 0 0" />
    <parent
      link="rstr_link" />
    <child
      link="fr_wheel" />
    <axis
      xyz="0 1 0" />
    <limit
      effort="100.0"
      velocity="200.0" />
  </joint>

  <transmission name="fr_tran">
    <type>transmission_interface/SimpleTransmission</type>
    <joint name="fr_axle">
      <hardwareInterface>hardware_interface/EffortJointInterface</hardwareInterface>
    </joint>
    <actuator name="fr_act">
      <!-- This hardwareInterface element exists for compatibility
           with ROS Hydro. -->
      <hardwareInterface>hardware_interface/EffortJointInterface</hardwareInterface>
      <mechanicalReduction>1</mechanicalReduction>
    </actuator>
  </transmission>
</robot>
